Traceback (most recent call last):
  File "/opt/homebrew/Caskroom/miniforge/base/envs/dojo-env/lib/python3.8/site-packages/jupyter_cache/executors/utils.py", line 51, in single_nb_execution
    executenb(
  File "/opt/homebrew/Caskroom/miniforge/base/envs/dojo-env/lib/python3.8/site-packages/nbclient/client.py", line 1204, in execute
    return NotebookClient(nb=nb, resources=resources, km=km, **kwargs).execute()
  File "/opt/homebrew/Caskroom/miniforge/base/envs/dojo-env/lib/python3.8/site-packages/nbclient/util.py", line 84, in wrapped
    return just_run(coro(*args, **kwargs))
  File "/opt/homebrew/Caskroom/miniforge/base/envs/dojo-env/lib/python3.8/site-packages/nbclient/util.py", line 62, in just_run
    return loop.run_until_complete(coro)
  File "/opt/homebrew/Caskroom/miniforge/base/envs/dojo-env/lib/python3.8/asyncio/base_events.py", line 616, in run_until_complete
    return future.result()
  File "/opt/homebrew/Caskroom/miniforge/base/envs/dojo-env/lib/python3.8/site-packages/nbclient/client.py", line 663, in async_execute
    await self.async_execute_cell(
  File "/opt/homebrew/Caskroom/miniforge/base/envs/dojo-env/lib/python3.8/site-packages/nbclient/client.py", line 965, in async_execute_cell
    await self._check_raise_for_error(cell, cell_index, exec_reply)
  File "/opt/homebrew/Caskroom/miniforge/base/envs/dojo-env/lib/python3.8/site-packages/nbclient/client.py", line 862, in _check_raise_for_error
    raise CellExecutionError.from_cell_and_msg(cell, exec_reply_content)
nbclient.exceptions.CellExecutionError: An error occurred while executing the following cell:
------------------
## Make x and y variables
target = None#'price'
drop_cols_model = []

y = df[target].copy()
X = df.drop(columns=[target,*drop_cols_model]).copy()

X_train, X_test, y_train, y_test = train_test_split(X,y, random_state=321)
X_train.head()
------------------

[0;31m---------------------------------------------------------------------------[0m
[0;31mKeyError[0m                                  Traceback (most recent call last)
File [0;32m/opt/homebrew/Caskroom/miniforge/base/envs/dojo-env/lib/python3.8/site-packages/pandas/core/indexes/base.py:3621[0m, in [0;36mIndex.get_loc[0;34m(self, key, method, tolerance)[0m
[1;32m   3620[0m [38;5;28;01mtry[39;00m:
[0;32m-> 3621[0m     [38;5;28;01mreturn[39;00m [38;5;28;43mself[39;49m[38;5;241;43m.[39;49m[43m_engine[49m[38;5;241;43m.[39;49m[43mget_loc[49m[43m([49m[43mcasted_key[49m[43m)[49m
[1;32m   3622[0m [38;5;28;01mexcept[39;00m [38;5;167;01mKeyError[39;00m [38;5;28;01mas[39;00m err:

File [0;32m/opt/homebrew/Caskroom/miniforge/base/envs/dojo-env/lib/python3.8/site-packages/pandas/_libs/index.pyx:136[0m, in [0;36mpandas._libs.index.IndexEngine.get_loc[0;34m()[0m

File [0;32m/opt/homebrew/Caskroom/miniforge/base/envs/dojo-env/lib/python3.8/site-packages/pandas/_libs/index.pyx:163[0m, in [0;36mpandas._libs.index.IndexEngine.get_loc[0;34m()[0m

File [0;32mpandas/_libs/hashtable_class_helper.pxi:5198[0m, in [0;36mpandas._libs.hashtable.PyObjectHashTable.get_item[0;34m()[0m

File [0;32mpandas/_libs/hashtable_class_helper.pxi:5206[0m, in [0;36mpandas._libs.hashtable.PyObjectHashTable.get_item[0;34m()[0m

[0;31mKeyError[0m: None

The above exception was the direct cause of the following exception:

[0;31mKeyError[0m                                  Traceback (most recent call last)
Input [0;32mIn [9][0m, in [0;36m<cell line: 5>[0;34m()[0m
[1;32m      2[0m target [38;5;241m=[39m [38;5;28;01mNone[39;00m[38;5;66;03m#'price'[39;00m
[1;32m      3[0m drop_cols_model [38;5;241m=[39m []
[0;32m----> 5[0m y [38;5;241m=[39m [43mdf[49m[43m[[49m[43mtarget[49m[43m][49m[38;5;241m.[39mcopy()
[1;32m      6[0m X [38;5;241m=[39m df[38;5;241m.[39mdrop(columns[38;5;241m=[39m[target,[38;5;241m*[39mdrop_cols_model])[38;5;241m.[39mcopy()
[1;32m      8[0m X_train, X_test, y_train, y_test [38;5;241m=[39m train_test_split(X,y, random_state[38;5;241m=[39m[38;5;241m321[39m)

File [0;32m/opt/homebrew/Caskroom/miniforge/base/envs/dojo-env/lib/python3.8/site-packages/pandas/core/frame.py:3505[0m, in [0;36mDataFrame.__getitem__[0;34m(self, key)[0m
[1;32m   3503[0m [38;5;28;01mif[39;00m [38;5;28mself[39m[38;5;241m.[39mcolumns[38;5;241m.[39mnlevels [38;5;241m>[39m [38;5;241m1[39m:
[1;32m   3504[0m     [38;5;28;01mreturn[39;00m [38;5;28mself[39m[38;5;241m.[39m_getitem_multilevel(key)
[0;32m-> 3505[0m indexer [38;5;241m=[39m [38;5;28;43mself[39;49m[38;5;241;43m.[39;49m[43mcolumns[49m[38;5;241;43m.[39;49m[43mget_loc[49m[43m([49m[43mkey[49m[43m)[49m
[1;32m   3506[0m [38;5;28;01mif[39;00m is_integer(indexer):
[1;32m   3507[0m     indexer [38;5;241m=[39m [indexer]

File [0;32m/opt/homebrew/Caskroom/miniforge/base/envs/dojo-env/lib/python3.8/site-packages/pandas/core/indexes/base.py:3623[0m, in [0;36mIndex.get_loc[0;34m(self, key, method, tolerance)[0m
[1;32m   3621[0m     [38;5;28;01mreturn[39;00m [38;5;28mself[39m[38;5;241m.[39m_engine[38;5;241m.[39mget_loc(casted_key)
[1;32m   3622[0m [38;5;28;01mexcept[39;00m [38;5;167;01mKeyError[39;00m [38;5;28;01mas[39;00m err:
[0;32m-> 3623[0m     [38;5;28;01mraise[39;00m [38;5;167;01mKeyError[39;00m(key) [38;5;28;01mfrom[39;00m [38;5;21;01merr[39;00m
[1;32m   3624[0m [38;5;28;01mexcept[39;00m [38;5;167;01mTypeError[39;00m:
[1;32m   3625[0m     [38;5;66;03m# If we have a listlike key, _check_indexing_error will raise[39;00m
[1;32m   3626[0m     [38;5;66;03m#  InvalidIndexError. Otherwise we fall through and re-raise[39;00m
[1;32m   3627[0m     [38;5;66;03m#  the TypeError.[39;00m
[1;32m   3628[0m     [38;5;28mself[39m[38;5;241m.[39m_check_indexing_error(key)

[0;31mKeyError[0m: None
KeyError: None

