Traceback (most recent call last):
  File "/opt/homebrew/Caskroom/miniforge/base/envs/dojo-env/lib/python3.8/site-packages/jupyter_cache/executors/utils.py", line 51, in single_nb_execution
    executenb(
  File "/opt/homebrew/Caskroom/miniforge/base/envs/dojo-env/lib/python3.8/site-packages/nbclient/client.py", line 1204, in execute
    return NotebookClient(nb=nb, resources=resources, km=km, **kwargs).execute()
  File "/opt/homebrew/Caskroom/miniforge/base/envs/dojo-env/lib/python3.8/site-packages/nbclient/util.py", line 84, in wrapped
    return just_run(coro(*args, **kwargs))
  File "/opt/homebrew/Caskroom/miniforge/base/envs/dojo-env/lib/python3.8/site-packages/nbclient/util.py", line 62, in just_run
    return loop.run_until_complete(coro)
  File "/opt/homebrew/Caskroom/miniforge/base/envs/dojo-env/lib/python3.8/asyncio/base_events.py", line 616, in run_until_complete
    return future.result()
  File "/opt/homebrew/Caskroom/miniforge/base/envs/dojo-env/lib/python3.8/site-packages/nbclient/client.py", line 663, in async_execute
    await self.async_execute_cell(
  File "/opt/homebrew/Caskroom/miniforge/base/envs/dojo-env/lib/python3.8/site-packages/nbclient/client.py", line 965, in async_execute_cell
    await self._check_raise_for_error(cell, cell_index, exec_reply)
  File "/opt/homebrew/Caskroom/miniforge/base/envs/dojo-env/lib/python3.8/site-packages/nbclient/client.py", line 862, in _check_raise_for_error
    raise CellExecutionError.from_cell_and_msg(cell, exec_reply_content)
nbclient.exceptions.CellExecutionError: An error occurred while executing the following cell:
------------------
scores = sf.evaluate_regression(rf_reg,X_te, y_te, X_train_df=X_tr, y_train=y_tr,
                            return_scores=True)
------------------

[0;31m---------------------------------------------------------------------------[0m
[0;31mTypeError[0m                                 Traceback (most recent call last)
Input [0;32mIn [74][0m, in [0;36m<cell line: 1>[0;34m()[0m
[0;32m----> 1[0m scores [38;5;241m=[39m [43msf[49m[38;5;241;43m.[39;49m[43mevaluate_regression[49m[43m([49m[43mrf_reg[49m[43m,[49m[43mX_te[49m[43m,[49m[43m [49m[43my_te[49m[43m,[49m[43m [49m[43mX_train_df[49m[38;5;241;43m=[39;49m[43mX_tr[49m[43m,[49m[43m [49m[43my_train[49m[38;5;241;43m=[39;49m[43my_tr[49m[43m,[49m
[1;32m      2[0m [43m                            [49m[43mreturn_scores[49m[38;5;241;43m=[39;49m[38;5;28;43;01mTrue[39;49;00m[43m)[49m

[0;31mTypeError[0m: evaluate_regression() got an unexpected keyword argument 'X_train_df'
TypeError: evaluate_regression() got an unexpected keyword argument 'X_train_df'

